2025-08-20 09:07:35.592 | INFO     | __main__:run_daemon:199 - Starting OHLC Update Scheduler in daemon mode
2025-08-20 09:07:35.593 | INFO     | __main__:setup_schedules:195 - Scheduled 1m: every_5_minutes
2025-08-20 09:07:35.593 | INFO     | __main__:setup_schedules:195 - Scheduled 15m: every_15_minutes
2025-08-20 09:07:35.593 | INFO     | __main__:setup_schedules:195 - Scheduled 1h: every_hour
2025-08-20 09:07:35.593 | INFO     | __main__:setup_schedules:195 - Scheduled 1d: daily_at_midnight
2025-08-20 09:07:35.593 | INFO     | __main__:setup_schedules:195 - Scheduled gap_check: daily_at_1am
2025-08-20 09:07:35.593 | INFO     | __main__:setup_schedules:195 - Scheduled health_check: every_30_minutes
2025-08-20 09:07:35.593 | INFO     | __main__:run_daemon:209 - Running initial updates...
2025-08-20 09:07:35.593 | INFO     | __main__:run_job:121 - Starting job: 1m
2025-08-20 09:07:35.595 | INFO     | __main__:run_job:121 - Starting job: 15m
2025-08-20 09:07:35.596 | INFO     | __main__:run_daemon:213 - Scheduler is running. Press Ctrl+C to stop.
2025-08-20 09:07:54.885 | SUCCESS  | __main__:monitor_job:173 - Job 15m completed successfully in 19.3 seconds
2025-08-20 09:07:55.747 | SUCCESS  | __main__:monitor_job:173 - Job 1m completed successfully in 20.2 seconds
2025-08-20 09:12:35.600 | INFO     | __main__:run_job:121 - Starting job: 1m
2025-08-20 09:12:54.935 | SUCCESS  | __main__:monitor_job:173 - Job 1m completed successfully in 19.3 seconds
2025-08-20 09:17:35.699 | INFO     | __main__:run_job:121 - Starting job: 1m
2025-08-20 09:17:54.786 | SUCCESS  | __main__:monitor_job:173 - Job 1m completed successfully in 19.1 seconds
2025-08-20 09:22:35.729 | INFO     | __main__:run_job:121 - Starting job: 15m
2025-08-20 09:22:35.731 | INFO     | __main__:run_job:121 - Starting job: 1m
2025-08-20 09:22:54.896 | SUCCESS  | __main__:monitor_job:173 - Job 15m completed successfully in 19.2 seconds
2025-08-20 09:22:55.857 | SUCCESS  | __main__:monitor_job:173 - Job 1m completed successfully in 20.1 seconds
2025-08-20 09:27:35.747 | INFO     | __main__:run_job:121 - Starting job: 1m
2025-08-20 09:27:55.111 | SUCCESS  | __main__:monitor_job:173 - Job 1m completed successfully in 19.4 seconds
2025-08-20 09:32:35.792 | INFO     | __main__:run_job:121 - Starting job: 1m
2025-08-20 09:32:55.220 | SUCCESS  | __main__:monitor_job:173 - Job 1m completed successfully in 19.4 seconds
2025-08-20 09:37:35.835 | INFO     | __main__:run_job:121 - Starting job: health_check
2025-08-20 09:37:35.841 | INFO     | __main__:run_job:121 - Starting job: 15m
2025-08-20 09:37:35.843 | INFO     | __main__:run_job:121 - Starting job: 1m
2025-08-20 09:37:53.719 | SUCCESS  | __main__:monitor_job:173 - Job 15m completed successfully in 17.9 seconds
2025-08-20 09:37:54.710 | SUCCESS  | __main__:monitor_job:173 - Job health_check completed successfully in 18.9 seconds
2025-08-20 09:37:55.037 | SUCCESS  | __main__:monitor_job:173 - Job 1m completed successfully in 19.2 seconds
2025-08-20 09:42:35.937 | INFO     | __main__:run_job:121 - Starting job: 1m
2025-08-20 09:43:38.982 | SUCCESS  | __main__:monitor_job:173 - Job 1m completed successfully in 63.0 seconds
2025-08-20 09:47:36.898 | INFO     | __main__:run_job:121 - Starting job: 1m
2025-08-20 09:47:56.422 | SUCCESS  | __main__:monitor_job:173 - Job 1m completed successfully in 19.5 seconds
2025-08-20 09:52:35.921 | INFO     | __main__:run_job:121 - Starting job: 15m
2025-08-20 09:52:36.928 | INFO     | __main__:run_job:121 - Starting job: 1m
2025-08-20 09:52:53.766 | SUCCESS  | __main__:monitor_job:173 - Job 15m completed successfully in 17.8 seconds
2025-08-20 09:52:57.749 | SUCCESS  | __main__:monitor_job:173 - Job 1m completed successfully in 20.8 seconds
2025-08-20 09:57:36.960 | INFO     | __main__:run_job:121 - Starting job: 1m
2025-08-20 09:57:56.296 | SUCCESS  | __main__:monitor_job:173 - Job 1m completed successfully in 19.3 seconds
2025-08-20 10:02:37.006 | INFO     | __main__:run_job:121 - Starting job: 1m
2025-08-20 10:02:56.619 | SUCCESS  | __main__:monitor_job:173 - Job 1m completed successfully in 19.6 seconds
2025-08-20 10:05:00.485 | INFO     | __main__:run_job:121 - Starting job: 1h
2025-08-20 10:05:17.682 | SUCCESS  | __main__:monitor_job:173 - Job 1h completed successfully in 17.2 seconds
2025-08-20 10:07:36.007 | INFO     | __main__:run_job:121 - Starting job: health_check
2025-08-20 10:07:36.011 | INFO     | __main__:run_job:121 - Starting job: 15m
2025-08-20 10:07:37.017 | INFO     | __main__:run_job:121 - Starting job: 1m
2025-08-20 10:07:53.790 | SUCCESS  | __main__:monitor_job:173 - Job 15m completed successfully in 17.8 seconds
2025-08-20 10:07:56.225 | SUCCESS  | __main__:monitor_job:173 - Job 1m completed successfully in 19.2 seconds
2025-08-20 10:07:57.790 | SUCCESS  | __main__:monitor_job:173 - Job health_check completed successfully in 21.8 seconds
2025-08-20 10:12:38.019 | INFO     | __main__:run_job:121 - Starting job: 1m
2025-08-20 10:12:57.420 | SUCCESS  | __main__:monitor_job:173 - Job 1m completed successfully in 19.4 seconds
2025-08-20 10:17:38.954 | INFO     | __main__:run_job:121 - Starting job: 1m
2025-08-20 10:17:58.652 | SUCCESS  | __main__:monitor_job:173 - Job 1m completed successfully in 19.7 seconds
2025-08-20 10:22:36.948 | INFO     | __main__:run_job:121 - Starting job: 15m
2025-08-20 10:22:38.969 | INFO     | __main__:run_job:121 - Starting job: 1m
2025-08-20 10:22:54.873 | SUCCESS  | __main__:monitor_job:173 - Job 15m completed successfully in 17.9 seconds
2025-08-20 10:22:58.333 | SUCCESS  | __main__:monitor_job:173 - Job 1m completed successfully in 19.4 seconds
2025-08-20 10:27:39.067 | INFO     | __main__:run_job:121 - Starting job: 1m
2025-08-20 10:27:58.612 | SUCCESS  | __main__:monitor_job:173 - Job 1m completed successfully in 19.5 seconds
2025-08-20 10:32:39.239 | INFO     | __main__:run_job:121 - Starting job: 1m
2025-08-20 10:32:58.888 | SUCCESS  | __main__:monitor_job:173 - Job 1m completed successfully in 19.6 seconds
2025-08-20 10:37:36.205 | INFO     | __main__:run_job:121 - Starting job: health_check
2025-08-20 10:37:37.222 | INFO     | __main__:run_job:121 - Starting job: 15m
2025-08-20 10:37:40.241 | INFO     | __main__:run_job:121 - Starting job: 1m
2025-08-20 10:37:55.491 | SUCCESS  | __main__:monitor_job:173 - Job 15m completed successfully in 18.3 seconds
2025-08-20 10:37:59.480 | SUCCESS  | __main__:monitor_job:173 - Job 1m completed successfully in 19.2 seconds
2025-08-20 10:38:01.052 | SUCCESS  | __main__:monitor_job:173 - Job health_check completed successfully in 24.8 seconds
2025-08-20 10:42:40.321 | INFO     | __main__:run_job:121 - Starting job: 1m
2025-08-20 10:43:00.087 | SUCCESS  | __main__:monitor_job:173 - Job 1m completed successfully in 19.8 seconds
2025-08-20 10:47:40.423 | INFO     | __main__:run_job:121 - Starting job: 1m
2025-08-20 10:47:59.566 | SUCCESS  | __main__:monitor_job:173 - Job 1m completed successfully in 19.1 seconds
2025-08-20 10:52:37.343 | INFO     | __main__:run_job:121 - Starting job: 15m
2025-08-20 10:52:41.382 | INFO     | __main__:run_job:121 - Starting job: 1m
2025-08-20 10:52:56.237 | SUCCESS  | __main__:monitor_job:173 - Job 15m completed successfully in 18.9 seconds
2025-08-20 10:53:00.684 | SUCCESS  | __main__:monitor_job:173 - Job 1m completed successfully in 19.3 seconds
2025-08-20 10:57:42.330 | INFO     | __main__:run_job:121 - Starting job: 1m
2025-08-20 10:58:02.087 | SUCCESS  | __main__:monitor_job:173 - Job 1m completed successfully in 19.8 seconds
2025-08-20 11:02:42.381 | INFO     | __main__:run_job:121 - Starting job: 1m
2025-08-20 11:03:02.522 | SUCCESS  | __main__:monitor_job:173 - Job 1m completed successfully in 20.1 seconds
2025-08-20 11:05:00.297 | INFO     | __main__:run_job:121 - Starting job: 1h
2025-08-20 11:05:18.001 | SUCCESS  | __main__:monitor_job:173 - Job 1h completed successfully in 17.7 seconds
2025-08-20 11:07:36.403 | INFO     | __main__:run_job:121 - Starting job: health_check
2025-08-20 11:07:37.415 | INFO     | __main__:run_job:121 - Starting job: 15m
2025-08-20 11:07:42.444 | INFO     | __main__:run_job:121 - Starting job: 1m
2025-08-20 11:07:55.262 | SUCCESS  | __main__:monitor_job:173 - Job 15m completed successfully in 17.8 seconds
2025-08-20 11:07:56.009 | SUCCESS  | __main__:monitor_job:173 - Job health_check completed successfully in 19.6 seconds
2025-08-20 11:08:01.453 | SUCCESS  | __main__:monitor_job:173 - Job 1m completed successfully in 19.0 seconds
2025-08-20 11:12:42.483 | INFO     | __main__:run_job:121 - Starting job: 1m
2025-08-20 11:13:01.940 | SUCCESS  | __main__:monitor_job:173 - Job 1m completed successfully in 19.5 seconds
2025-08-20 11:17:42.511 | INFO     | __main__:run_job:121 - Starting job: 1m
2025-08-20 11:18:02.776 | SUCCESS  | __main__:monitor_job:173 - Job 1m completed successfully in 20.3 seconds
2025-08-20 11:22:37.806 | INFO     | __main__:run_job:121 - Starting job: 15m
2025-08-20 11:22:42.826 | INFO     | __main__:run_job:121 - Starting job: 1m
2025-08-20 11:22:56.278 | SUCCESS  | __main__:monitor_job:173 - Job 15m completed successfully in 18.5 seconds
2025-08-20 11:23:02.328 | SUCCESS  | __main__:monitor_job:173 - Job 1m completed successfully in 19.5 seconds
2025-08-20 11:27:42.849 | INFO     | __main__:run_job:121 - Starting job: 1m
2025-08-20 11:28:15.877 | SUCCESS  | __main__:monitor_job:173 - Job 1m completed successfully in 33.0 seconds
2025-08-20 11:32:42.890 | INFO     | __main__:run_job:121 - Starting job: 1m
2025-08-20 11:33:02.509 | SUCCESS  | __main__:monitor_job:173 - Job 1m completed successfully in 19.6 seconds
2025-08-20 11:37:36.938 | INFO     | __main__:run_job:121 - Starting job: health_check
2025-08-20 11:37:37.949 | INFO     | __main__:run_job:121 - Starting job: 15m
2025-08-20 11:37:42.968 | INFO     | __main__:run_job:121 - Starting job: 1m
2025-08-20 11:37:56.369 | SUCCESS  | __main__:monitor_job:173 - Job 15m completed successfully in 18.4 seconds
2025-08-20 11:38:02.072 | SUCCESS  | __main__:monitor_job:173 - Job 1m completed successfully in 19.1 seconds
2025-08-20 11:38:02.339 | SUCCESS  | __main__:monitor_job:173 - Job health_check completed successfully in 25.4 seconds
2025-08-20 11:42:43.022 | INFO     | __main__:run_job:121 - Starting job: 1m
2025-08-20 11:43:02.733 | SUCCESS  | __main__:monitor_job:173 - Job 1m completed successfully in 19.7 seconds
2025-08-20 11:47:43.086 | INFO     | __main__:run_job:121 - Starting job: 1m
2025-08-20 11:48:02.311 | SUCCESS  | __main__:monitor_job:173 - Job 1m completed successfully in 19.2 seconds
2025-08-20 11:52:38.135 | INFO     | __main__:run_job:121 - Starting job: 15m
2025-08-20 11:52:43.157 | INFO     | __main__:run_job:121 - Starting job: 1m
2025-08-20 11:52:55.734 | SUCCESS  | __main__:monitor_job:173 - Job 15m completed successfully in 17.6 seconds
2025-08-20 11:53:02.147 | SUCCESS  | __main__:monitor_job:173 - Job 1m completed successfully in 19.0 seconds
2025-08-20 11:57:43.186 | INFO     | __main__:run_job:121 - Starting job: 1m
2025-08-20 11:58:02.688 | SUCCESS  | __main__:monitor_job:173 - Job 1m completed successfully in 19.5 seconds
2025-08-20 12:02:44.166 | INFO     | __main__:run_job:121 - Starting job: 1m
2025-08-20 12:03:03.685 | SUCCESS  | __main__:monitor_job:173 - Job 1m completed successfully in 19.5 seconds
2025-08-20 12:05:00.653 | INFO     | __main__:run_job:121 - Starting job: 1h
2025-08-20 12:05:17.683 | SUCCESS  | __main__:monitor_job:173 - Job 1h completed successfully in 17.0 seconds
2025-08-20 12:07:37.174 | INFO     | __main__:run_job:121 - Starting job: health_check
2025-08-20 12:07:38.181 | INFO     | __main__:run_job:121 - Starting job: 15m
2025-08-20 12:07:44.201 | INFO     | __main__:run_job:121 - Starting job: 1m
2025-08-20 12:07:55.224 | SUCCESS  | __main__:monitor_job:173 - Job health_check completed successfully in 18.0 seconds
2025-08-20 12:07:55.808 | SUCCESS  | __main__:monitor_job:173 - Job 15m completed successfully in 17.6 seconds
2025-08-20 12:08:03.375 | SUCCESS  | __main__:monitor_job:173 - Job 1m completed successfully in 19.2 seconds
2025-08-20 12:12:45.162 | INFO     | __main__:run_job:121 - Starting job: 1m
2025-08-20 12:13:05.239 | SUCCESS  | __main__:monitor_job:173 - Job 1m completed successfully in 20.1 seconds
2025-08-20 12:17:45.194 | INFO     | __main__:run_job:121 - Starting job: 1m
2025-08-20 12:18:05.369 | SUCCESS  | __main__:monitor_job:173 - Job 1m completed successfully in 20.2 seconds
2025-08-20 12:22:38.236 | INFO     | __main__:run_job:121 - Starting job: 15m
2025-08-20 12:22:45.266 | INFO     | __main__:run_job:121 - Starting job: 1m
2025-08-20 12:22:56.177 | SUCCESS  | __main__:monitor_job:173 - Job 15m completed successfully in 17.9 seconds
2025-08-20 12:23:05.152 | SUCCESS  | __main__:monitor_job:173 - Job 1m completed successfully in 19.9 seconds
2025-08-20 12:27:45.311 | INFO     | __main__:run_job:121 - Starting job: 1m
2025-08-20 12:28:05.232 | SUCCESS  | __main__:monitor_job:173 - Job 1m completed successfully in 19.9 seconds
2025-08-20 12:32:46.174 | INFO     | __main__:run_job:121 - Starting job: 1m
2025-08-20 12:33:05.737 | SUCCESS  | __main__:monitor_job:173 - Job 1m completed successfully in 19.6 seconds
2025-08-20 12:37:37.455 | INFO     | __main__:run_job:121 - Starting job: health_check
2025-08-20 12:37:38.463 | INFO     | __main__:run_job:121 - Starting job: 15m
2025-08-20 12:37:46.486 | INFO     | __main__:run_job:121 - Starting job: 1m
2025-08-20 12:37:55.850 | SUCCESS  | __main__:monitor_job:173 - Job 15m completed successfully in 17.4 seconds
2025-08-20 12:38:00.752 | SUCCESS  | __main__:monitor_job:173 - Job health_check completed successfully in 23.3 seconds
2025-08-20 12:38:05.838 | SUCCESS  | __main__:monitor_job:173 - Job 1m completed successfully in 19.4 seconds
2025-08-20 12:42:46.512 | INFO     | __main__:run_job:121 - Starting job: 1m
2025-08-20 12:43:06.291 | SUCCESS  | __main__:monitor_job:173 - Job 1m completed successfully in 19.8 seconds
2025-08-20 12:47:47.514 | INFO     | __main__:run_job:121 - Starting job: 1m
2025-08-20 12:48:07.343 | SUCCESS  | __main__:monitor_job:173 - Job 1m completed successfully in 19.8 seconds
2025-08-20 12:52:38.507 | INFO     | __main__:run_job:121 - Starting job: 15m
2025-08-20 12:52:47.541 | INFO     | __main__:run_job:121 - Starting job: 1m
2025-08-20 12:52:56.595 | SUCCESS  | __main__:monitor_job:173 - Job 15m completed successfully in 18.1 seconds
2025-08-20 12:53:07.343 | SUCCESS  | __main__:monitor_job:173 - Job 1m completed successfully in 19.8 seconds
2025-08-20 12:57:47.575 | INFO     | __main__:run_job:121 - Starting job: 1m
2025-08-20 12:58:07.585 | SUCCESS  | __main__:monitor_job:173 - Job 1m completed successfully in 20.0 seconds
2025-08-20 13:02:47.586 | INFO     | __main__:run_job:121 - Starting job: 1m
2025-08-20 13:03:06.789 | SUCCESS  | __main__:monitor_job:173 - Job 1m completed successfully in 19.2 seconds
2025-08-20 13:05:00.027 | INFO     | __main__:run_job:121 - Starting job: 1h
2025-08-20 13:05:16.816 | SUCCESS  | __main__:monitor_job:173 - Job 1h completed successfully in 16.8 seconds
2025-08-20 13:07:37.942 | INFO     | __main__:run_job:121 - Starting job: health_check
2025-08-20 13:07:38.952 | INFO     | __main__:run_job:121 - Starting job: 15m
2025-08-20 13:07:48.007 | INFO     | __main__:run_job:121 - Starting job: 1m
2025-08-20 13:07:56.735 | SUCCESS  | __main__:monitor_job:173 - Job 15m completed successfully in 17.8 seconds
2025-08-20 13:08:00.251 | SUCCESS  | __main__:monitor_job:173 - Job health_check completed successfully in 22.3 seconds
2025-08-20 13:08:07.347 | SUCCESS  | __main__:monitor_job:173 - Job 1m completed successfully in 19.3 seconds
2025-08-20 13:12:48.848 | INFO     | __main__:run_job:121 - Starting job: 1m
2025-08-20 13:13:08.432 | SUCCESS  | __main__:monitor_job:173 - Job 1m completed successfully in 19.6 seconds
2025-08-20 13:17:49.771 | INFO     | __main__:run_job:121 - Starting job: 1m
2025-08-20 13:18:09.395 | SUCCESS  | __main__:monitor_job:173 - Job 1m completed successfully in 19.6 seconds
2025-08-20 13:22:39.593 | INFO     | __main__:run_job:121 - Starting job: 15m
2025-08-20 13:22:50.669 | INFO     | __main__:run_job:121 - Starting job: 1m
2025-08-20 13:22:58.395 | SUCCESS  | __main__:monitor_job:173 - Job 15m completed successfully in 18.8 seconds
2025-08-20 13:23:09.908 | SUCCESS  | __main__:monitor_job:173 - Job 1m completed successfully in 19.2 seconds
2025-08-20 13:27:51.505 | INFO     | __main__:run_job:121 - Starting job: 1m
2025-08-20 13:28:10.920 | SUCCESS  | __main__:monitor_job:173 - Job 1m completed successfully in 19.4 seconds
2025-08-20 13:32:52.325 | INFO     | __main__:run_job:121 - Starting job: 1m
2025-08-20 13:33:11.999 | SUCCESS  | __main__:monitor_job:173 - Job 1m completed successfully in 19.7 seconds
2025-08-20 13:37:38.026 | INFO     | __main__:run_job:121 - Starting job: health_check
2025-08-20 13:37:40.044 | INFO     | __main__:run_job:121 - Starting job: 15m
2025-08-20 13:37:53.112 | INFO     | __main__:run_job:121 - Starting job: 1m
2025-08-20 13:37:57.963 | SUCCESS  | __main__:monitor_job:173 - Job 15m completed successfully in 17.9 seconds
2025-08-20 13:38:02.288 | SUCCESS  | __main__:monitor_job:173 - Job health_check completed successfully in 24.3 seconds
2025-08-20 13:38:12.194 | SUCCESS  | __main__:monitor_job:173 - Job 1m completed successfully in 19.1 seconds
2025-08-20 13:42:53.822 | INFO     | __main__:run_job:121 - Starting job: 1m
2025-08-20 13:43:13.495 | SUCCESS  | __main__:monitor_job:173 - Job 1m completed successfully in 19.7 seconds
2025-08-20 13:47:54.645 | INFO     | __main__:run_job:121 - Starting job: 1m
2025-08-20 13:48:13.958 | SUCCESS  | __main__:monitor_job:173 - Job 1m completed successfully in 19.3 seconds
2025-08-20 13:52:40.442 | INFO     | __main__:run_job:121 - Starting job: 15m
2025-08-20 13:52:55.512 | INFO     | __main__:run_job:121 - Starting job: 1m
2025-08-20 13:52:58.092 | SUCCESS  | __main__:monitor_job:173 - Job 15m completed successfully in 17.6 seconds
2025-08-20 13:53:14.929 | SUCCESS  | __main__:monitor_job:173 - Job 1m completed successfully in 19.4 seconds
2025-08-20 13:57:56.244 | INFO     | __main__:run_job:121 - Starting job: 1m
2025-08-20 13:58:15.441 | SUCCESS  | __main__:monitor_job:173 - Job 1m completed successfully in 19.2 seconds
2025-08-20 14:02:57.039 | INFO     | __main__:run_job:121 - Starting job: 1m
2025-08-20 14:03:16.721 | SUCCESS  | __main__:monitor_job:173 - Job 1m completed successfully in 19.7 seconds
2025-08-20 14:05:00.729 | INFO     | __main__:run_job:121 - Starting job: 1h
2025-08-20 14:05:18.381 | SUCCESS  | __main__:monitor_job:173 - Job 1h completed successfully in 17.7 seconds
2025-08-20 14:07:38.676 | INFO     | __main__:run_job:121 - Starting job: health_check
2025-08-20 14:07:40.699 | INFO     | __main__:run_job:121 - Starting job: 15m
2025-08-20 14:07:57.792 | SUCCESS  | __main__:monitor_job:173 - Job health_check completed successfully in 19.1 seconds
2025-08-20 14:07:57.803 | INFO     | __main__:run_job:121 - Starting job: 1m
2025-08-20 14:07:58.460 | SUCCESS  | __main__:monitor_job:173 - Job 15m completed successfully in 17.8 seconds
2025-08-20 14:08:17.153 | SUCCESS  | __main__:monitor_job:173 - Job 1m completed successfully in 19.4 seconds
2025-08-20 14:12:58.114 | INFO     | __main__:run_job:121 - Starting job: 1m
2025-08-20 14:13:17.252 | SUCCESS  | __main__:monitor_job:173 - Job 1m completed successfully in 19.1 seconds
2025-08-20 14:17:58.147 | INFO     | __main__:run_job:121 - Starting job: 1m
2025-08-20 14:18:17.954 | SUCCESS  | __main__:monitor_job:173 - Job 1m completed successfully in 19.8 seconds
2025-08-20 14:22:41.643 | INFO     | __main__:run_job:121 - Starting job: 15m
2025-08-20 14:22:58.765 | INFO     | __main__:run_job:121 - Starting job: 1m
2025-08-20 14:22:59.930 | SUCCESS  | __main__:monitor_job:173 - Job 15m completed successfully in 18.3 seconds
2025-08-20 14:23:18.059 | SUCCESS  | __main__:monitor_job:173 - Job 1m completed successfully in 19.3 seconds
2025-08-20 14:27:59.683 | INFO     | __main__:run_job:121 - Starting job: 1m
2025-08-20 14:28:19.602 | SUCCESS  | __main__:monitor_job:173 - Job 1m completed successfully in 19.9 seconds
2025-08-20 14:32:59.951 | INFO     | __main__:run_job:121 - Starting job: 1m
2025-08-20 14:33:19.533 | SUCCESS  | __main__:monitor_job:173 - Job 1m completed successfully in 19.6 seconds
2025-08-20 14:37:38.881 | INFO     | __main__:run_job:121 - Starting job: health_check
2025-08-20 14:37:41.900 | INFO     | __main__:run_job:121 - Starting job: 15m
2025-08-20 14:37:58.143 | SUCCESS  | __main__:monitor_job:173 - Job health_check completed successfully in 19.3 seconds
2025-08-20 14:37:59.312 | SUCCESS  | __main__:monitor_job:173 - Job 15m completed successfully in 17.4 seconds
2025-08-20 14:37:59.965 | INFO     | __main__:run_job:121 - Starting job: 1m
2025-08-20 14:38:19.269 | SUCCESS  | __main__:monitor_job:173 - Job 1m completed successfully in 19.3 seconds
2025-08-20 14:43:00.043 | INFO     | __main__:run_job:121 - Starting job: 1m
2025-08-20 14:43:19.269 | SUCCESS  | __main__:monitor_job:173 - Job 1m completed successfully in 19.2 seconds
2025-08-20 14:48:00.051 | INFO     | __main__:run_job:121 - Starting job: 1m
2025-08-20 14:48:19.925 | SUCCESS  | __main__:monitor_job:173 - Job 1m completed successfully in 19.9 seconds
2025-08-20 14:52:42.034 | INFO     | __main__:run_job:121 - Starting job: 15m
2025-08-20 14:53:00.098 | INFO     | __main__:run_job:121 - Starting job: 1m
2025-08-20 14:53:00.759 | SUCCESS  | __main__:monitor_job:173 - Job 15m completed successfully in 18.7 seconds
2025-08-20 14:53:18.941 | SUCCESS  | __main__:monitor_job:173 - Job 1m completed successfully in 18.8 seconds
2025-08-20 14:58:01.091 | INFO     | __main__:run_job:121 - Starting job: 1m
2025-08-20 14:58:20.798 | SUCCESS  | __main__:monitor_job:173 - Job 1m completed successfully in 19.7 seconds
2025-08-20 15:03:01.125 | INFO     | __main__:run_job:121 - Starting job: 1m
2025-08-20 15:03:20.939 | SUCCESS  | __main__:monitor_job:173 - Job 1m completed successfully in 19.8 seconds
2025-08-20 15:05:00.552 | INFO     | __main__:run_job:121 - Starting job: 1h
2025-08-20 15:05:17.999 | SUCCESS  | __main__:monitor_job:173 - Job 1h completed successfully in 17.4 seconds
2025-08-20 15:07:39.331 | INFO     | __main__:run_job:121 - Starting job: health_check
2025-08-20 15:07:42.363 | INFO     | __main__:run_job:121 - Starting job: 15m
2025-08-20 15:08:00.067 | SUCCESS  | __main__:monitor_job:173 - Job 15m completed successfully in 17.7 seconds
2025-08-20 15:08:01.500 | INFO     | __main__:run_job:121 - Starting job: 1m
2025-08-20 15:08:03.982 | SUCCESS  | __main__:monitor_job:173 - Job health_check completed successfully in 24.6 seconds
2025-08-20 15:08:21.179 | SUCCESS  | __main__:monitor_job:173 - Job 1m completed successfully in 19.7 seconds
2025-08-20 15:13:02.266 | INFO     | __main__:run_job:121 - Starting job: 1m
2025-08-20 15:13:22.014 | SUCCESS  | __main__:monitor_job:173 - Job 1m completed successfully in 19.7 seconds
2025-08-20 15:18:03.222 | INFO     | __main__:run_job:121 - Starting job: 1m
2025-08-20 15:18:22.694 | SUCCESS  | __main__:monitor_job:173 - Job 1m completed successfully in 19.5 seconds
2025-08-20 15:22:43.042 | INFO     | __main__:run_job:121 - Starting job: 15m
2025-08-20 15:23:00.704 | SUCCESS  | __main__:monitor_job:173 - Job 15m completed successfully in 17.7 seconds
2025-08-20 15:23:04.182 | INFO     | __main__:run_job:121 - Starting job: 1m
2025-08-20 15:23:23.796 | SUCCESS  | __main__:monitor_job:173 - Job 1m completed successfully in 19.6 seconds
2025-08-20 15:28:04.705 | INFO     | __main__:run_job:121 - Starting job: 1m
2025-08-20 15:28:24.044 | SUCCESS  | __main__:monitor_job:173 - Job 1m completed successfully in 19.3 seconds
2025-08-20 15:33:04.752 | INFO     | __main__:run_job:121 - Starting job: 1m
2025-08-20 15:33:24.287 | SUCCESS  | __main__:monitor_job:173 - Job 1m completed successfully in 19.5 seconds
2025-08-20 15:37:39.715 | INFO     | __main__:run_job:121 - Starting job: health_check
2025-08-20 15:37:43.730 | INFO     | __main__:run_job:121 - Starting job: 15m
2025-08-20 15:38:01.639 | SUCCESS  | __main__:monitor_job:173 - Job 15m completed successfully in 17.9 seconds
2025-08-20 15:38:04.809 | INFO     | __main__:run_job:121 - Starting job: 1m
2025-08-20 15:38:05.418 | SUCCESS  | __main__:monitor_job:173 - Job health_check completed successfully in 25.7 seconds
2025-08-20 15:38:24.142 | SUCCESS  | __main__:monitor_job:173 - Job 1m completed successfully in 19.3 seconds
2025-08-20 15:43:04.841 | INFO     | __main__:run_job:121 - Starting job: 1m
2025-08-20 15:43:24.539 | SUCCESS  | __main__:monitor_job:173 - Job 1m completed successfully in 19.7 seconds
2025-08-20 15:48:04.859 | INFO     | __main__:run_job:121 - Starting job: 1m
2025-08-20 15:48:24.532 | SUCCESS  | __main__:monitor_job:173 - Job 1m completed successfully in 19.7 seconds
2025-08-20 15:52:43.861 | INFO     | __main__:run_job:121 - Starting job: 15m
2025-08-20 15:53:02.214 | SUCCESS  | __main__:monitor_job:173 - Job 15m completed successfully in 18.4 seconds
2025-08-20 15:53:04.926 | INFO     | __main__:run_job:121 - Starting job: 1m
2025-08-20 15:53:24.121 | SUCCESS  | __main__:monitor_job:173 - Job 1m completed successfully in 19.2 seconds
